2023-05-06 22:54:20,458 INFO    StreamThr :22023 [internal.py:wandb_internal():86] W&B internal server running at pid: 22023, started at: 2023-05-06 22:54:20.457693
2023-05-06 22:54:20,461 DEBUG   HandlerThread:22023 [handler.py:handle_request():144] handle_request: status
2023-05-06 22:54:20,464 INFO    WriterThread:22023 [datastore.py:open_for_write():85] open: save/deneme1/wandb/run-20230506_225420-r5ala9g7/run-r5ala9g7.wandb
2023-05-06 22:54:20,465 DEBUG   SenderThread:22023 [sender.py:send():375] send: header
2023-05-06 22:54:20,468 DEBUG   SenderThread:22023 [sender.py:send():375] send: run
2023-05-06 22:54:22,740 ERROR   SenderThread:22023 [internal_api.py:execute():288] 401 response executing GraphQL.
2023-05-06 22:54:22,740 ERROR   SenderThread:22023 [internal_api.py:execute():289] {"errors":[{"message":"user is not logged in","path":["upsertBucket"],"extensions":{"code":"PERMISSION_ERROR"}}],"data":{"upsertBucket":null}}
2023-05-06 22:54:22,741 ERROR   SenderThread:22023 [sender.py:send_run():979] The API key you provided is either invalid or missing.  If the `WANDB_API_KEY` environment variable is set, make sure it is correct. Otherwise, to resolve this issue, you may try running the 'wandb login --relogin' command. If you are using a local server, make sure that you're using the correct hostname. If you're not sure, you can try logging in again using the 'wandb login --relogin --host [hostname]' command.(Error 401: Unauthorized)
Traceback (most recent call last):
  File "/home/colors/.local/lib/python3.10/site-packages/wandb/sdk/lib/retry.py", line 131, in __call__
    result = self._call_fn(*args, **kwargs)
  File "/home/colors/.local/lib/python3.10/site-packages/wandb/sdk/internal/internal_api.py", line 285, in execute
    return self.client.execute(*args, **kwargs)  # type: ignore
  File "/home/colors/.local/lib/python3.10/site-packages/wandb/vendor/gql-0.2.0/wandb_gql/client.py", line 52, in execute
    result = self._get_result(document, *args, **kwargs)
  File "/home/colors/.local/lib/python3.10/site-packages/wandb/vendor/gql-0.2.0/wandb_gql/client.py", line 60, in _get_result
    return self.transport.execute(document, *args, **kwargs)
  File "/home/colors/.local/lib/python3.10/site-packages/wandb/sdk/lib/gql_request.py", line 56, in execute
    request.raise_for_status()
  File "/usr/lib/python3/dist-packages/requests/models.py", line 943, in raise_for_status
    raise HTTPError(http_error_msg, response=self)
requests.exceptions.HTTPError: 401 Client Error: Unauthorized for url: https://api.wandb.ai/graphql

During handling of the above exception, another exception occurred:

Traceback (most recent call last):
  File "/home/colors/.local/lib/python3.10/site-packages/wandb/sdk/internal/sender.py", line 977, in send_run
    self._init_run(run, config_value_dict)
  File "/home/colors/.local/lib/python3.10/site-packages/wandb/sdk/internal/sender.py", line 1015, in _init_run
    server_run, inserted, server_messages = self._api.upsert_run(
  File "/home/colors/.local/lib/python3.10/site-packages/wandb/apis/normalize.py", line 73, in wrapper
    raise err
  File "/home/colors/.local/lib/python3.10/site-packages/wandb/apis/normalize.py", line 41, in wrapper
    return func(*args, **kwargs)
  File "/home/colors/.local/lib/python3.10/site-packages/wandb/sdk/internal/internal_api.py", line 1690, in upsert_run
    response = self.gql(
  File "/home/colors/.local/lib/python3.10/site-packages/wandb/sdk/internal/internal_api.py", line 257, in gql
    ret = self._retry_gql(
  File "/home/colors/.local/lib/python3.10/site-packages/wandb/sdk/lib/retry.py", line 147, in __call__
    retry_timedelta_triggered = check_retry_fn(e)
  File "/home/colors/.local/lib/python3.10/site-packages/wandb/util.py", line 907, in check_retry_fn
    return fallback_retry_fn(e)
  File "/home/colors/.local/lib/python3.10/site-packages/wandb/util.py", line 838, in no_retry_auth
    raise AuthenticationError(
wandb.errors.AuthenticationError: The API key you provided is either invalid or missing.  If the `WANDB_API_KEY` environment variable is set, make sure it is correct. Otherwise, to resolve this issue, you may try running the 'wandb login --relogin' command. If you are using a local server, make sure that you're using the correct hostname. If you're not sure, you can try logging in again using the 'wandb login --relogin --host [hostname]' command.(Error 401: Unauthorized)
2023-05-06 22:54:25,743 DEBUG   HandlerThread:22023 [handler.py:handle_request():144] handle_request: status_report
2023-05-06 22:54:30,744 DEBUG   HandlerThread:22023 [handler.py:handle_request():144] handle_request: status_report
2023-05-06 22:54:35,745 DEBUG   HandlerThread:22023 [handler.py:handle_request():144] handle_request: status_report
2023-05-06 22:54:40,747 DEBUG   HandlerThread:22023 [handler.py:handle_request():144] handle_request: status_report
2023-05-06 22:54:45,748 DEBUG   HandlerThread:22023 [handler.py:handle_request():144] handle_request: status_report
2023-05-06 22:54:50,750 DEBUG   HandlerThread:22023 [handler.py:handle_request():144] handle_request: status_report
2023-05-06 22:54:55,751 DEBUG   HandlerThread:22023 [handler.py:handle_request():144] handle_request: status_report
2023-05-06 22:54:57,734 DEBUG   HandlerThread:22023 [handler.py:handle_request():144] handle_request: shutdown
2023-05-06 22:54:57,734 INFO    HandlerThread:22023 [handler.py:finish():845] shutting down handler
2023-05-06 22:54:57,752 INFO    SenderThread:22023 [sender.py:finish():1550] shutting down sender
2023-05-06 22:54:57,752 INFO    WriterThread:22023 [datastore.py:close():298] close: save/deneme1/wandb/run-20230506_225420-r5ala9g7/run-r5ala9g7.wandb
